<?xml version="1.0" ?>
<robot name="a0509">
  
  <link name="base"/>
  <joint name="fixed" type="fixed">
    <parent link="base"/>
    <child link="base_0"/>
  </joint>
  
  <link name="base_0">
	<inertial>
	  <mass value="3.722"/>
	  <origin xyz="-1.2e-05 -6e-05 0.050723"/>
      <inertia ixx="0.011" ixy="-7.19e-06" ixz="-1.94e-06" iyy="0.011" iyz="4.9e-06" izz="0.014"/>
    </inertial>
	<visual>
      <origin rpy="0 0 0" xyz="0 0 0"/>
      <geometry>
        <mesh filename="package://mesh/doosan-robot2/dsr_description2/meshes/a0509_blue/A0509_0_0.dae" scale="0.001 0.001 0.001"/>
      </geometry>
    </visual>
  </link>

  <joint name="joint1" type="revolute">
    <parent link="base_0"/>
    <child link="link1"/>
    <origin rpy="0 0 0" xyz="0 0 0.1555"/>
    <axis xyz="0 0 1"/>
    <limit effort="30" lower="-2.617" upper="2.617" velocity="1.571"/>
  </joint>

  <link name="link1">
	<inertial>
	  <mass value="7.446"/>
	  <origin xyz="7e-05 0.044281 0.143327"/>
      <inertia ixx="0.039" ixy="2.1e-05" ixz="-3.61e-05" iyy="0.023" iyz="-0.003" izz="0.039"/>
    </inertial>
    <visual>
      <origin rpy="0 0 0" xyz="0 0 0"/>
      <geometry>
        <mesh filename="package://mesh/doosan-robot2/dsr_description2/meshes/a0509_blue/A0509_1_0.dae" scale="0.001 0.001 0.001"/>
      </geometry>
    </visual>
    <visual>
      <origin rpy="0 0 0" xyz="0 0 0"/>
      <geometry>
        <mesh filename="package://mesh/doosan-robot2/dsr_description2/meshes/a0509_blue/A0509_1_1.dae" scale="0.001 0.001 0.001"/>
      </geometry>
    </visual>
    <visual>
      <origin rpy="0 0 0" xyz="0 0 0"/>
      <geometry>
        <mesh filename="package://mesh/doosan-robot2/dsr_description2/meshes/a0509_blue/A0509_1_2.dae" scale="0.001 0.001 0.001"/>
      </geometry>
    </visual>
  </link>
  
  <joint name="joint2" type="revolute">
    <parent link="link1"/>
    <child link="link2"/>
    <origin rpy="0 -1.571 -1.571" xyz="0 0 0"/>
    <axis xyz="0 0 1"/>
    <limit effort="30" lower="-2.617" upper="2.617" velocity="1.571"/>
  </joint>

  <link name="link2">
	<inertial>
	  <mass value="10.569"/>
	  <origin xyz="-1.6e-05 0.189372 0.418558"/>
      <inertia ixx="0.820" ixy="1.19e-05" ixz="-0.000263" iyy="0.82" iyz="-0.008" izz="0.031"/>
    </inertial>
    <visual>
      <origin rpy="0 0 0" xyz="0 0 0"/>
      <geometry>
        <mesh filename="package://mesh/doosan-robot2/dsr_description2/meshes/a0509_blue/A0509_2_0.dae" scale="0.001 0.001 0.001"/>
      </geometry>
    </visual>
    <visual>
      <origin rpy="0 0 0" xyz="0 0 0"/>
      <geometry>     
		<mesh filename="package://mesh/doosan-robot2/dsr_description2/meshes/a0509_blue/A0509_2_1.dae" scale="0.001 0.001 0.001"/>
      </geometry>
	  </visual>
    <visual>
      <origin rpy="0 0 0" xyz="0 0 0"/>
      <geometry>     
		<mesh filename="package://mesh/doosan-robot2/dsr_description2/meshes/a0509_blue/A0509_2_2.dae" scale="0.001 0.001 0.001"/>
      </geometry>
    </visual>	
  </link>

  <joint name="joint3" type="revolute">
    <parent link="link2"/>
    <child link="link3"/>
    <origin rpy="0 0 1.571" xyz="0.409 0 0"/>
    <axis xyz="0 0 1"/>
    <limit effort="30" lower="-2.617" upper="2.617" velocity="1.571"/>
  </joint>
  
  <link name="link3">
	<inertial>
	  <mass value="3.614"/>
	  <origin xyz="6e-06 0.07917 0.781807"/>
      <inertia ixx="0.012" ixy="-4.38e-06" ixz="-1.2e-06" iyy="0.008" iyz="0.002" izz="0.011"/>
    </inertial>
    <visual>
      <origin rpy="0 0 0" xyz="0 0 0"/>
      <geometry>     
		<mesh filename="package://mesh/doosan-robot2/dsr_description2/meshes/a0509_blue/A0509_3_0.dae" scale="0.001 0.001 0.001"/>
      </geometry>
    </visual>
    <visual>
      <origin rpy="0 0 0" xyz="0 0 0"/>
      <geometry>     
		<mesh filename="package://mesh/doosan-robot2/dsr_description2/meshes/a0509_blue/A0509_3_1.dae" scale="0.001 0.001 0.001"/>
      </geometry>
    </visual>
  </link>

  <joint name="joint4" type="revolute">
    <parent link="link3"/>
    <child link="link4"/>
    <origin rpy="1.571 0 0" xyz="0 -0.367 0"/>
    <axis xyz="0 0 1"/>
    <limit effort="30" lower="-2.617" upper="2.617" velocity="1.571"/>
  </joint>
  
  <link name="link4">
	<inertial>
	  <mass value="3.785"/>
	  <origin xyz="-2.1e-05 0.12337 1.148"/>
      <inertia ixx="0.177" ixy="-2.34e-06" ixz="-4.92e-06" iyy="0.161" iyz="-0.05" izz="0.022"/>
    </inertial>
    <visual>
      <origin rpy="0 0 0" xyz="0 0 0"/>
      <geometry>     
		<mesh filename="package://mesh/doosan-robot2/dsr_description2/meshes/a0509_blue/A0509_4_0.dae" scale="0.001 0.001 0.001"/>
      </geometry>
    </visual>
    <visual>
      <origin rpy="0 0 0" xyz="0 0 0"/>
      <geometry>     
		<mesh filename="package://mesh/doosan-robot2/dsr_description2/meshes/a0509_blue/A0509_4_1.dae" scale="0.001 0.001 0.001"/>
      </geometry>
    </visual>
  </link>

  <joint name="joint5" type="revolute">
    <parent link="link4"/>
    <child link="link5"/>
    <origin rpy="-1.571 0 0" xyz="0 0 0"/>
    <axis xyz="0 0 1"/>
    <limit effort="30" lower="-2.617" upper="2.617" velocity="1.571"/>
  </joint>
  
  <link name="link5">
	<inertial>
	  <mass value="2.598"/>
	  <origin xyz="-1.7e-05 0.06662 1.33103"/>
      <inertia ixx="0.007" ixy="-4.93e-06" ixz="-5.57e-06" iyy="0.004" iyz="-6.64e-05" izz="0.007"/>
    </inertial>
    <visual>
      <origin rpy="0 0 0" xyz="0 0 0"/>
      <geometry>     
		<mesh filename="package://mesh/doosan-robot2/dsr_description2/meshes/a0509_blue/A0509_5_0.dae" scale="0.001 0.001 0.001"/>
      </geometry>
    </visual>
    <visual>
      <origin rpy="0 0 0" xyz="0 0 0"/>
      <geometry>     
		<mesh filename="package://mesh/doosan-robot2/dsr_description2/meshes/a0509_blue/A0509_5_1.dae" scale="0.001 0.001 0.001"/>
      </geometry>
    </visual>
  </link>

  <joint name="joint6" type="revolute">
    <parent link="link5"/>
    <child link="link6"/>
    <origin rpy="1.571 0 0" xyz="0 -0.124 0"/>
    <axis xyz="0 0 1"/>
    <limit effort="30" lower="-2.617" upper="2.617" velocity="1.571"/>
  </joint>
  
  <link name="link6">
	<inertial>
	  <mass value="1.128"/>
	  <origin xyz="-0.000174 0.034708 1.40022"/>
      <inertia ixx="0.001" ixy="-2.79e-06" ixz="5.78e-06" iyy="0.001" iyz="-6.67e-06" izz="0.001"/>
    </inertial>
    <visual>
      <origin rpy="0 0 0" xyz="0 0 0"/>
      <geometry>     
		<mesh filename="package://mesh/doosan-robot2/dsr_description2/meshes/a0509_blue/A0509_6_0.dae" scale="0.001 0.001 0.001"/>
      </geometry>
    </visual>
  </link>
  
   <link name="right_hand">
    <collision>
      <origin rpy="0 0 0" xyz="0 0 0"/>
      <geometry>
        <cylinder length="0" radius="0"/>
      </geometry>
    </collision>
    <inertial>
      <origin rpy="0 0 0" xyz="1e-08 1e-08 1e-08"/>
      <mass value="1e-08"/>
      <inertia ixx="1e-08" ixy="1e-08" ixz="1e-08" iyy="1e-08" iyz="1e-08" izz="1e-08"/>
    </inertial>
  </link>
  <joint name="right_hand" type="fixed">
    <origin rpy="0 0 0.0" xyz="0 0 0.0"/>
    <axis xyz="0 0 0"/>
    <parent link="link6"/>
    <child link="right_hand"/>
  </joint>
  
  <!-- Weiss Gripper WSG50 -->

  <!-- ============================================================================= -->

  <!-- BASE LINK -->
  <link name="gripper_base_link">
      <inertial>
          <mass value="1.2" />
          <origin xyz="0 0 0" />
        <!--inertia ixx="1.0" ixy="0.0" ixz="0.0"
               iyy="100.0" iyz="0.0" 
               izz="1.0" /-->
          <inertia  ixx="1.0" ixy="0.0"  ixz="0.0"  iyy="1.0"  iyz="0.0"  izz="1.0" />
      </inertial>

      <visual>
          <origin xyz="0.0 0 0" rpy="0 0 0" />
          <geometry>
             <mesh filename="package://mesh/doosan-robot2/dsr_description2/meshes/wsg50/WSG50_110.stl" scale="1 1 1"/>
       <!--box size="0.146 0.05 0.0735"/-->
          </geometry>
          <material name="grey">
            <color rgba="0.5 0.5 0.5 1"/>
          </material>
      </visual>

      <collision>
          <origin xyz="0.0 0 0" rpy="0 0 0" />
          <geometry>
       <!--box size="0.146 0.05 0.0735"/-->
             <mesh filename="package://mesh/doosan-robot2/dsr_description2/meshes/wsg50/WSG50_110.stl" scale="1 1 1"/>
         </geometry>
     </collision>
  </link>


  <gazebo reference="gripper_base_link">
    <material>Gazebo/Grey</material>
    <turnGravityOff>false</turnGravityOff>
  </gazebo>

  <!-- GRIPPER LEFT -->

  <joint name="base_joint_gripper_left" type="prismatic">
     <limit lower="-0.055" upper="-0.0027" effort="1.0" velocity="1.0"/>
     <origin xyz="0 0 0" rpy="0 0 0" />      <!--origin xyz="-0.0067 0 0.049" rpy="0 0 0" /-->
     <parent link="gripper_base_link"/>
     <child link="gripper_left" />
     <dynamics friction="100" damping="100" />
     <axis xyz="1 0 0"/>
     <limit effort="100" velocity="100"/>
  </joint>

  <transmission name="base_trans_left" type="pr2_mechanism_model/SimpleTransmission">
     <actuator name="base_motor_left" />
     <joint name="base_joint_gripper_left" />
     <mechanicalReduction>1</mechanicalReduction>
     <motorTorqueConstant>1</motorTorqueConstant>
  </transmission>

  <link name="gripper_left">
      <inertial>
          <mass value="0.1" />
          <origin xyz="0 0 0" />
      <inertia ixx="1.0" ixy="0.0" ixz="0.0"
               iyy="1.0" iyz="0.0" 
               izz="1.0" />
      </inertial>

      <visual>
          <origin xyz="0.0 0 0" rpy="0 0 0" />
          <geometry>
             <mesh filename="package://mesh/doosan-robot2/dsr_description2/meshes/wsg50/GUIDE_WSG50_110.stl" scale="0.001 0.001 0.001"/>
       <!--box size="0.0175 0.03 0.024"/-->
          </geometry>
          <material name="white">
            <color rgba="1. 1. 1. 1"/>
          </material>
      </visual>

      <collision>
          <origin xyz="0 0 0" rpy="0 0 0" />
          <geometry>
       <!--box size="0.0175 0.03 0.024"/-->
             <mesh filename="package://mesh/doosan-robot2/dsr_description2/meshes/wsg50/GUIDE_WSG50_110.stl" scale="0.001 0.001 0.001"/>
         </geometry>
     </collision>
  </link>

  <gazebo reference="gripper_left">
    <material>Gazebo/Blue</material>
    <turnGravityOff>false</turnGravityOff>
  </gazebo>


  <!-- LEFT FINGER -->

  <joint name="guide_joint_finger_left" type="fixed">
     <origin xyz="0 0 0.023" rpy="0 0 0" />
     <parent link="gripper_left"/>
     <child link="finger_left" />
     <dynamics friction="100" damping="100" />
     <axis xyz="1 0 0"/>
     <limit effort="100" velocity="100"/>
  </joint>

  <link name="finger_left">

      <contact>
        <lateral_friction value="1"/>
        <rolling_friction value="0.1"/>
        <contact_cfm value="0.0"/>
        <contact_erp value="1.0"/>
      </contact>

      <inertial>
          <mass value="0.1" />
          <origin xyz="0 0 0" />
      <inertia ixx="1.0" ixy="0.0" ixz="0.0"
               iyy="1.0" iyz="0.0" 
               izz="1.0" />
      </inertial>

      <visual>
          <origin xyz="0.003 0.015 0.057" rpy="1.57 0 -1.57" />
          <geometry>
             <mesh filename="package://mesh/doosan-robot2/dsr_description2/meshes/wsg50/DIGIT-WSG-50-V1.STL" scale="0.001 0.001 0.001"/>
          </geometry>
          <material name="white">
            <color rgba="1. 1. 1. 1"/>
          </material>
      </visual>

      <collision>
          <origin xyz="0.003 0.015 0.057" rpy="1.57 0 -1.57" />
          <geometry>
             <mesh filename="package://mesh/doosan-robot2/dsr_description2/meshes/wsg50/DIGIT-WSG-50-V1.STL" scale="0.001 0.001 0.001"/>
         </geometry>
     </collision>
  </link>

  <gazebo reference="finger_left">
    <material>Gazebo/Blue</material>
    <turnGravityOff>false</turnGravityOff>
  </gazebo>


  <joint name="joint_finger_tip_left" type="fixed">
     <!-- <origin xyz="0 0 0.023" rpy="0 0 0" /> -->
     <origin xyz="-0.006 0 0.08" rpy="0 0 0" />
     <parent link="finger_left"/>
     <child link="finger_left_tip" />
     <dynamics friction="100" damping="100" />
     <axis xyz="1 0 0"/>
     <limit effort="100" velocity="100"/>
  </joint>

  <link name="finger_left_tip">

      <contact>
        <lateral_friction value="1"/>
        <rolling_friction value="0.1"/>
        <contact_cfm value="0.0"/>
        <contact_erp value="1.0"/>
      </contact>

      <inertial>
          <mass value="0.1" />
          <origin xyz="0 0 0" />
      <inertia ixx="1.0" ixy="0.0" ixz="0.0"
               iyy="1.0" iyz="0.0" 
               izz="1.0" />
      </inertial>

      <visual>
          <!-- <origin xyz="-0.006 0 0.057" rpy="0 0 0" /> -->
          <geometry>
             <mesh filename="package://mesh/doosan-robot2/dsr_description2/meshes/wsg50/digit.STL"/>
          </geometry>
          <material name="white">
            <color rgba="1. 1. 1. 1"/>
          </material>
      </visual>

      <collision>
          <!-- <origin xyz="-0.006 0 0.057" rpy="0 0 0" /> -->
          <geometry>
             <mesh filename="package://mesh/doosan-robot2/dsr_description2/meshes/wsg50/digit.STL"/>
         </geometry>
     </collision>
  </link>

  <!-- GRIPPER RIGHT -->

  <joint name="base_joint_gripper_right" type="prismatic">
     <limit lower="0.0027" upper="0.055" effort="1.0" velocity="1.0"/>
     <origin xyz="0 0 0" rpy="0 0 3.14159" />
     <parent link="gripper_base_link"/>
     <child link="gripper_right" />
     <axis xyz="-1 0 0"/>
     <dynamics friction="100" damping="100" />
     <limit effort="100" velocity="100"/>
  </joint>

  <transmission name="base_trans_right" type="pr2_mechanism_model/SimpleTransmission">
     <actuator name="base_motor_right" />
     <joint name="base_joint_gripper_right" />
     <mechanicalReduction>1</mechanicalReduction>
     <motorTorqueConstant>1</motorTorqueConstant>
  </transmission>
  
    <link name="gripper_right">
      <inertial>
          <mass value="0.1" />
          <origin xyz="0 0 0" />
      <inertia ixx="1.0" ixy="0.0" ixz="0.0"
               iyy="1.0" iyz="0.0" 
               izz="1.0" />
      </inertial>

      <visual>
          <origin xyz="0.0 0 0" rpy="0 0 0" />
          <geometry>
             <mesh filename="package://mesh/doosan-robot2/dsr_description2/meshes/wsg50/GUIDE_WSG50_110.stl" scale="0.001 0.001 0.001"/>
       <!--box size="0.0175 0.03 0.024"/-->
          </geometry>
          <material name="white">
            <color rgba="1. 1. 1. 1"/>
          </material>
      </visual>

      <collision>
          <origin xyz="0 0 0" rpy="0 0 0" />
          <geometry>
       <!--box size="0.0175 0.03 0.024"/-->
             <mesh filename="package://mesh/doosan-robot2/dsr_description2/meshes/wsg50/GUIDE_WSG50_110.stl" scale="0.001 0.001 0.001"/>
         </geometry>
     </collision>
  </link>

  <gazebo reference="gripper_right">
    <material>Gazebo/White</material>
    <turnGravityOff>false</turnGravityOff>
  </gazebo>

  <!-- RIGHT FINGER -->

  <joint name="guide_joint_finger_right" type="fixed">
     <origin xyz="0 0 0.023" rpy="0 0 0" />
     <parent link="gripper_right"/>
     <child link="finger_right" />
     <dynamics friction="100" damping="100" />
     <axis xyz="1 0 0"/>
     <limit effort="100" velocity="100"/>
  </joint>

  <link name="finger_right">

      <contact>
        <lateral_friction value="1"/>
        <rolling_friction value="0.1"/>
        <contact_cfm value="0.0"/>
        <contact_erp value="1.0"/>
      </contact>

      <inertial>
          <mass value="0.1" />
          <origin xyz="0 0 0" />
      <inertia ixx="1.0" ixy="0.0" ixz="0.0"
               iyy="1.0" iyz="0.0" 
               izz="1.0" />
      </inertial>

      <visual>
          <origin xyz="0.003 0.015 0.057" rpy="1.57 0 -1.57" />
          <geometry>
             <mesh filename="package://mesh/doosan-robot2/dsr_description2/meshes/wsg50/DIGIT-WSG-50-V1.STL" scale="0.001 0.001 0.001"/>
          </geometry>
          <material name="white">
            <color rgba="1. 1. 1. 1"/>
          </material>
      </visual>

      <collision>
          <origin xyz="0.003 0.015 0.057" rpy="1.57 0 -1.57" />
          <geometry>
             <mesh filename="package://mesh/doosan-robot2/dsr_description2/meshes/wsg50/DIGIT-WSG-50-V1.STL" scale="0.001 0.001 0.001"/>
         </geometry>
     </collision>
  </link>

  <joint name="joint_finger_tip_right" type="fixed">

      <origin xyz="-0.006 0 0.08" rpy="0 0 0" />
     <!-- <origin xyz="0 0 0.023" rpy="0 0 0" /> -->
     <parent link="finger_right"/>
     <child link="finger_right_tip" />
     <dynamics friction="100" damping="100" />
     <axis xyz="1 0 0"/>
     <limit effort="100" velocity="100"/>
  </joint>

  <link name="finger_right_tip">

      <contact>
        <lateral_friction value="1"/>
        <rolling_friction value="0.1"/>
        <contact_cfm value="0.0"/>
        <contact_erp value="1.0"/>
      </contact>

      <inertial>
          <mass value="0.1" />
          <origin xyz="0 0 0" />
      <inertia ixx="1.0" ixy="0.0" ixz="0.0"
               iyy="1.0" iyz="0.0" 
               izz="1.0" />
      </inertial>

      <visual>
          <!-- <origin xyz="-0.006 0 0.057" rpy="0 0 0" /> -->
          <geometry>
             <mesh filename="package://mesh/doosan-robot2/dsr_description2/meshes/wsg50/digit.STL"/>
          </geometry>
          <material name="white">
            <color rgba="1. 1. 1. 1"/>
          </material>
      </visual>

      <collision>
          <!-- <origin xyz="-0.006 0 0.057" rpy="0 0 0" /> -->
          <geometry>
             <mesh filename="package://mesh/doosan-robot2/dsr_description2/meshes/wsg50/digit.STL"/>
         </geometry>
     </collision>
  </link>


  <!-- ##################. Connect WSG50 to Sawyer ################## -->
  <joint name="arm_gripper_joint" type="fixed">
    <parent link="right_hand"/>
    <child link="gripper_base_link"/>
    <origin rpy="0.0 0.0 0.0" xyz="0.0 0.0 0.0"/>
  </joint>
  
</robot>
